Workbook
Name Engagement_Q3: Analysis!$B$5
Name Engagement_Threshold: Analysis!$B$5
Name Slicer_Discount_Category: #N/A
Name Slicer_Price_Category: #N/A
Name Slicer_Rating_Category: #N/A

Sheet Raw data
A1: Product | B1: Current price | C1: old price | D1: Discount | E1: Review | F1: Ratingd
A2: 115 Piece Set Of Multifunctional Precision Screwdrivers | B2: KSh 950 | C2: KSh 1,525 | D2: 0.38 | E2: -2 | F2: 4.5 out of 5
A3: Metal Decorative Hooks Key Hangers Entryway Wall Hooks Towel Hooks - Home | B3: KSh 527 | C3: KSh 999 | D3: 0.47 | E3: -14 | F3: 4.1 out of 5
A4: Portable Mini Cordless Car Vacuum Cleaner - Blue | B4: KSh 2,199 | C4: KSh 2,923 | D4: 0.25 | E4: -24 | F4: 4.6 out of 5
A5: Weighing Scale Digital Bathroom Body Fat Scale USB-Black | B5: KSh 1,580 | C5: KSh 2,499 | D5: 0.37 | E5: -7 | F5: 4.7 out of 5
A6: Portable Home Small Air Humidifier 3-Speed Fan - Green | B6: KSh 1,740 | C6: KSh 2,356 | D6: 0.26 | E6: -5 | F6: 4.8 out of 5
A7: 220V 60W Electric Soldering Iron Kits With Tools, Tips, And Multimeter | B7: KSh 2,999 | C7: KSh 3,290 | D7: 0.09 | E7: -15 | F7: 4 out of 5
A8: 137 Pieces Cake Decorating Tool Set Baking Supplies | B8: KSh 2,319 | C8: KSh 3,032 | D8: 0.24 | E8: -55 | F8: 4.6 out of 5
A9: Desk Foldable Fan Adjustable Fan Strong Wind 3 Gear Usb | B9: KSh 988 | C9: KSh 1,580 | D9: 0.37 | E9: -2 | F9: 4 out of 5
A10: LASA FOLDING TABLE SERVING STAND | B10: KSh 1,274 | C10: KSh 2,800 | D10: 0.55 | E10: -5 | F10: 4.8 out of 5
A11: 13 In 1 Home Repair Tools Box Kit Set | B11: KSh 1,600 | C11: KSh 2,929 | D11: 0.45 | E11: -5 | F11: 3.8 out of 5
A12: Genebre 115 In 1 Screwdriver Repairing Tool Set For IPhone Cellphone Hand Tool | B12: KSh 799 | C12: KSh 999 | D12: 0.2 | E12: -12 | F12: 4.1 out of 5
A13: 100 Pcs Crochet Hook Tool Set Knitting Hook Set With Box | B13: KSh 990 | C13: KSh 1,500 | D13: 0.34 | E13: -39 | F13: 4.7 out of 5
... A22: 3PCS Single Head Knitting Crochet Sweater Needle Set | B22: KSh 38 | C22: KSh 80 | D22: 0.53 | E22: -13 | F22: 3.3 out of 5
A23: 4pcs Bathroom/Kitchen Towel Rack,Roll Paper Holder,Towel Bars,Hook | B23: KSh 1,860 | C23: KSh 3,220 | D23: 0.42
A24: LED Romantic Spaceship Starry Sky Projector,Children's Bedroom Night Light-Blue | B24: KSh 880 | C24: KSh 1,350 | D24: 0.35 | E24: -6 | F24: 4 out of 5
A25: Foldable Overbed Table/Desk | B25: KSh 1,650 | C25: KSh 2,150 | D25: 0.23 | E25: -14 | F25: 4.4 out of 5
A26: LASA 3 Tier Bamboo Shoe Bench Storage Shelf | B26: KSh 2,048 | C26: KSh 4,500 | D26: 0.54 | E26: -7 | F26: 4.3 out of 5
A27: Electronic Digital Display Vernier Caliper | B27: KSh 420 | C27: KSh 647 | D27: 0.35 | E27: -49 | F27: 4.6 out of 5
A28: Portable Wardrobe Nonwoven With 3 Hanging Rods And 6 Storage Shelves | B28: KSh 2,880 | C28: KSh 3,520 | D28: 0.18 | E28: -12 | F28: 3.8 out of 5
A29: 12 Litre Black Insulated Lunch Box | B29: KSh 1,350 | C29: KSh 1,990 | D29: 0.32 | E29: -13 | F29: 3.8 out of 5
A30: 52 Pieces Cake Decorating Tool Set Gift Kit Baking Supplies | B30: KSh 1,758 | C30: KSh 2,499 | D30: 0.3 | E30: -20 | F30: 4.1 out of 5
A31: MultiFunctional Storage Rack Multi-layer Bookshelf | B31: KSh 2,200 | C31: KSh 4,080 | D31: 0.46
A32: Exfoliate And Exfoliate Face Towel - Black | B32: KSh 185 | C32: KSh 382 | D32: 0.52 | E32: -9 | F32: 4.3 out of 5
A33: 12 Litre Insulated Lunch Box Grey | B33: KSh 980 | C33: KSh 1,490 | D33: 0.34 | E33: -12 | F33: 4.7 out of 5
A34: LED Eye Protection Desk Lamp , Study, Reading, USB Fan - Double Pen Holder | B34: KSh 1,820 | C34: KSh 3,490 | D34: 0.48 | E34: -9 | F34: 4.3 out of 5
A35: 53Pcs/Set Yarn Knitting Crochet Hooks With Bag - Fortune Cat | B35: KSh 1,940 | C35: KSh 2,650 | D35: 0.27 | E35: -20 | F35: 4.7 out of 5
A36: 53 Pieces/Set Yarn Knitting Crochet Hooks With Bag - Pansies | B36: KSh 1,980 | C36: KSh 2,699 | D36: 0.27 | E36: -32 | F36: 4.5 out of 5
A37: DIY File Folder, Office Drawer File Holder, Pen Holder, Desktop Storage Rack | B37: KSh 1,620 | C37: KSh 2,690 | D37: 0.4 | E37: -1 | F37: 5 out of 5
A38: Classic Black Cat Cotton Hemp Pillow Case For Home Car | B38: KSh 171 | C38: KSh 360 | D38: 0.53 | E38: -2 | F38: 5 out of 5
A39: Punch-free Great Load Bearing Bathroom Storage Rack Wall Shelf-White | B39: KSh 389 | C39: KSh 656 | D39: 0.41 | E39: -36 | F39: 4.3 out of 5
A40: 1/2/3 Seater Elastic Sofa Cover,Living Room/Home Decor Chair Cover-Grey | B40: KSh 1,620 - KSh 1,980 | C40: KSh 2,200 - KSh 3,200 | D40: 0.38 | E40: -2 | F40: 4.5 out of 5
A41: LASA Stainless Steel Double Wall Mount Soap Dispenser - 500ml | B41: KSh 2,750 | C41: KSh 4,471 | D41: 0.38
A42: 4M Float Switch Water Level Controller -Water Tank | B42: KSh 475 | C42: KSh 931 | D42: 0.49
A43: Modern Sofa Throw Pillow Cover-45x45cm-Blue&Red | B43: KSh 238 | C43: KSh 476 | D43: 0.5
A44: Balloon Insert, Birthday Party Balloon Set, PU Leather | B44: KSh 610 | C44: KSh 1,060 | D44: 0.42
A45: Balloon Insert, Birthday Party Balloon Set, PU Leather | B45: KSh 610 | C45: KSh 1,060 | D45: 0.42
A46: Shower Cap Wide Elastic Band Cover Reusable Bashroom Cap | B46: KSh 2,132 | C46: KSh 2,169 | D46: 0.02
A47: Christmas Elk Fence Yard Lawn Decorations Cute For Holidays | B47: KSh 999 | C47: KSh 2,000 | D47: 0.5
A48: 60W Hot Melt Glue Sprayer - Efficient And Stable Glue Dispensing | B48: KSh 1,190 | C48: KSh 1,785 | D48: 0.33
...

Sheet tblProducts
A1: Product | B1: Current Price | C1: Old Price | D1: Discount | E1: Review | F1: Rating | G1: Discount Amount | H1: Rating Category | I1: Discount Category | J1: Price Category | K1: Engagement | L1: High discount + low rating | M1: High discount + low engagement | N1: Many reviews + average rating | O1: Strong engagement + excellent rating | P1: Rating Status | Q1: Calculated Discount | R1: Discount Difference | S1: Rating check | T1: Discount Check | U1: Price check
A2: 115 Piece Set Of Multifunctional Precision Screwdrivers | B2: 950 | C2: 1525 | D2: 0.38 | E2: 2 | F2: 4.5 | G2: =Cleaned_Data[[#This Row],[Old Price]]-Cleaned_Data[[#This Row],[Current Price]] -> 575 | H2: =IF(Cleaned_Data[[#This Row],[Rating]]="","Missing",IF(Cleaned_Data[[#This Row],[Rating]]<3,"Poor",IF(Cleaned_Data[[#This Row],[Rating]]<=4.5,"Average","Excellent"))) -> Average | I2: =IF( Cleaned_Data[[#This Row],[Discount]]="", "Missing", IF( Cleaned_Data[[#This Row],[Discount]]<20%, "Low Discount", IF( Cleaned_Data[[#This Row],[Discount]]<=40%, "Medium Discount", "High Discount" ) ) ) -> Medium Discount | J2: =IF( Cleaned_Data[[#This Row],[Current Price]]="", "Missing", IF( Cleaned_Data[[#This Row],[Current Price]]<=Analysis!$B$3, "Low Price", IF( Cleaned_Data[[#This Row],[Current Price]]<=Analysis!$B$4, "Medium Price", "High Price" ) ) ) -> Medium Price | K2: =IF(Cleaned_Data[[#This Row],[Review]]="","Missing",IF(Cleaned_Data[[#This Row],[Review]]>=Engagement_Threshold,"Strong Engagement","Weak Engagement")) -> Weak Engagement | L2: =IF(OR(Cleaned_Data[[#This Row],[Discount]]="",Cleaned_Data[[#This Row],[Rating]]=""),"Missing",IF(AND(Cleaned_Data[[#This Row],[Discount Category]]="High Discount",Cleaned_Data[[#This Row],[Rating Category]]="Poor"),"Flag","OK")) -> OK | M2: =IF(OR(Cleaned_Data[[#This Row],[Discount]]="",Cleaned_Data[[#This Row],[Review]]=""),"Missing",IF(AND(Cleaned_Data[[#This Row],[Discount Category]]="High Discount",Cleaned_Data[[#This Row],[Engagement]]="Weak Engagement"),"Flag","OK")) -> OK | N2: =IF(OR(Cleaned_Data[[#This Row],[Review]]="",Cleaned_Data[[#This Row],[Rating]]=""),"Missing",IF(AND(Cleaned_Data[[#This Row],[Engagement]]="Strong Engagement",Cleaned_Data[[#This Row],[Rating Category]]="Average"),"Flag","OK")) -> OK | O2: =IF(OR(Cleaned_Data[[#This Row],[Review]]="",Cleaned_Data[[#This Row],[Rating]]=""),"Missing",IF(AND(Cleaned_Data[[#This Row],[Engagement]]="Strong Engagement",Cleaned_Data[[#This Row],[Rating Category]]="Excellent"),"Flag","OK")) -> OK | P2: =IF(Cleaned_Data[[#This Row],[Rating]]="","Missing Rating","Has Rating") -> Has Rating | Q2: =IFERROR( (Cleaned_Data[[#This Row],[Old Price]]-Cleaned_Data[[#This Row],[Current Price]])/Cleaned_Data[[#This Row],[Old Price]], "" ) -> 0.37704918 | R2: =IF( Cleaned_Data[[#This Row],[Discount]] - Cleaned_Data[[#This Row],[Calculated Discount]]>2%, "Check", "OK" ) -> OK | S2: =IF(OR(Cleaned_Data[[#This Row],[Rating]]<0,Cleaned_Data[[#This Row],[Rating]]>5),"Check rating","OK") -> OK | T2: =IF(OR(Cleaned_Data[[#This Row],[Discount]]<0,Cleaned_Data[[#This Row],[Discount]]>1),"Check discount","OK") -> OK | U2: =IF(Cleaned_Data[[#This Row],[Current Price]]>Cleaned_Data[[#This Row],[Old Price]],"Check prices","OK") -> OK
A3: Metal Decorative Hooks Key Hangers Entryway Wall Hooks Towel Hooks - Home | B3: 527 | C3: 999 | D3: 0.47 | E3: 14 | F3: 4.1 | G3: =Cleaned_Data[[#This Row],[Old Price]]-Cleaned_Data[[#This Row],[Current Price]] -> 472 | H3: =IF(Cleaned_Data[[#This Row],[Rating]]="","Missing",IF(Cleaned_Data[[#This Row],[Rating]]<3,"Poor",IF(Cleaned_Data[[#This Row],[Rating]]<=4.5,"Average","Excellent"))) -> Average | I3: =IF( Cleaned_Data[[#This Row],[Discount]]="", "Missing", IF( Cleaned_Data[[#This Row],[Discount]]<20%, "Low Discount", IF( Cleaned_Data[[#This Row],[Discount]]<=40%, "Medium Discount", "High Discount" ) ) ) -> High Discount | J3: =IF( Cleaned_Data[[#This Row],[Current Price]]="", "Missing", IF( Cleaned_Data[[#This Row],[Current Price]]<=Analysis!$B$3, "Low Price", IF( Cleaned_Data[[#This Row],[Current Price]]<=Analysis!$B$4, "Medium Price", "High Price" ) ) ) -> Medium Price | K3: =IF(Cleaned_Data[[#This Row],[Review]]="","Missing",IF(Cleaned_Data[[#This Row],[Review]]>=Engagement_Threshold,"Strong Engagement","Weak Engagement")) -> Strong Engagement | L3: =IF(OR(Cleaned_Data[[#This Row],[Discount]]="",Cleaned_Data[[#This Row],[Rating]]=""),"Missing",IF(AND(Cleaned_Data[[#This Row],[Discount Category]]="High Discount",Cleaned_Data[[#This Row],[Rating Category]]="Poor"),"Flag","OK")) -> OK | M3: =IF(OR(Cleaned_Data[[#This Row],[Discount]]="",Cleaned_Data[[#This Row],[Review]]=""),"Missing",IF(AND(Cleaned_Data[[#This Row],[Discount Category]]="High Discount",Cleaned_Data[[#This Row],[Engagement]]="Weak Engagement"),"Flag","OK")) -> OK | N3: =IF(OR(Cleaned_Data[[#This Row],[Review]]="",Cleaned_Data[[#This Row],[Rating]]=""),"Missing",IF(AND(Cleaned_Data[[#This Row],[Engagement]]="Strong Engagement",Cleaned_Data[[#This Row],[Rating Category]]="Average"),"Flag","OK")) -> Flag | O3: =IF(OR(Cleaned_Data[[#This Row],[Review]]="",Cleaned_Data[[#This Row],[Rating]]=""),"Missing",IF(AND(Cleaned_Data[[#This Row],[Engagement]]="Strong Engagement",Cleaned_Data[[#This Row],[Rating Category]]="Excellent"),"Flag","OK")) -> OK | P3: =IF(Cleaned_Data[[#This Row],[Rating]]="","Missing Rating","Has Rating") -> Has Rating | Q3: =IFERROR( (Cleaned_Data[[#This Row],[Old Price]]-Cleaned_Data[[#This Row],[Current Price]])/Cleaned_Data[[#This Row],[Old Price]], "" ) -> 0.47247247 | R3: =IF( Cleaned_Data[[#This Row],[Discount]] - Cleaned_Data[[#This Row],[Calculated Discount]]>2%, "Check", "OK" ) -> OK | S3: =IF(OR(Cleaned_Data[[#This Row],[Rating]]<0,Cleaned_Data[[#This Row],[Rating]]>5),"Check rating","OK") -> OK | T3: =IF(OR(Cleaned_Data[[#This Row],[Discount]]<0,Cleaned_Data[[#This Row],[Discount]]>1),"Check discount","OK") -> OK | U3: =IF(Cleaned_Data[[#This Row],[Current Price]]>Cleaned_Data[[#This Row],[Old Price]],"Check prices","OK") -> OK
A4: Portable Mini Cordless Car Vacuum Cleaner - Blue | B4: 2199 | C4: 2923 | D4: 0.25 | E4: 24 | F4: 4.6 | G4: =Cleaned_Data[[#This Row],[Old Price]]-Cleaned_Data[[#This Row],[Current Price]] -> 724 | H4: =IF(Cleaned_Data[[#This Row],[Rating]]="","Missing",IF(Cleaned_Data[[#This Row],[Rating]]<3,"Poor",IF(Cleaned_Data[[#This Row],[Rating]]<=4.5,"Average","Excellent"))) -> Excellent | I4: =IF( Cleaned_Data[[#This Row],[Discount]]="", "Missing", IF( Cleaned_Data[[#This Row],[Discount]]<20%, "Low Discount", IF( Cleaned_Data[[#This Row],[Discount]]<=40%, "Medium Discount", "High Discount" ) ) ) -> Medium Discount | J4: =IF( Cleaned_Data[[#This Row],[Current Price]]="", "Missing", IF( Cleaned_Data[[#This Row],[Current Price]]<=Analysis!$B$3, "Low Price", IF( Cleaned_Data[[#This Row],[Current Price]]<=Analysis!$B$4, "Medium Price", "High Price" ) ) ) -> High Price | K4: =IF(Cleaned_Data[[#This Row],[Review]]="","Missing",IF(Cleaned_Data[[#This Row],[Review]]>=Engagement_Threshold,"Strong Engagement","Weak Engagement")) -> Strong Engagement | L4: =IF(OR(Cleaned_Data[[#This Row],[Discount]]="",Cleaned_Data[[#This Row],[Rating]]=""),"Missing",IF(AND(Cleaned_Data[[#This Row],[Discount Category]]="High Discount",Cleaned_Data[[#This Row],[Rating Category]]="Poor"),"Flag","OK")) -> OK | M4: =IF(OR(Cleaned_Data[[#This Row],[Discount]]="",Cleaned_Data[[#This Row],[Review]]=""),"Missing",IF(AND(Cleaned_Data[[#This Row],[Discount Category]]="High Discount",Cleaned_Data[[#This Row],[Engagement]]="Weak Engagement"),"Flag","OK")) -> OK | N4: =IF(OR(Cleaned_Data[[#This Row],[Review]]="",Cleaned_Data[[#This Row],[Rating]]=""),"Missing",IF(AND(Cleaned_Data[[#This Row],[Engagement]]="Strong Engagement",Cleaned_Data[[#This Row],[Rating Category]]="Average"),"Flag","OK")) -> OK | O4: =IF(OR(Cleaned_Data[[#This Row],[Review]]="",Cleaned_Data[[#This Row],[Rating]]=""),"Missing",IF(AND(Cleaned_Data[[#This Row],[Engagement]]="Strong Engagement",Cleaned_Data[[#This Row],[Rating Category]]="Excellent"),"Flag","OK")) -> Flag | P4: =IF(Cleaned_Data[[#This Row],[Rating]]="","Missing Rating","Has Rating") -> Has Rating | Q4: =IFERROR( (Cleaned_Data[[#This Row],[Old Price]]-Cleaned_Data[[#This Row],[Current Price]])/Cleaned_Data[[#This Row],[Old Price]], "" ) -> 0.24769073 | R4: =IF( Cleaned_Data[[#This Row],[Discount]] - Cleaned_Data[[#This Row],[Calculated Discount]]>2%, "Check", "OK" ) -> OK | S4: =IF(OR(Cleaned_Data[[#This Row],[Rating]]<0,Cleaned_Data[[#This Row],[Rating]]>5),"Check rating","OK") -> OK | T4: =IF(OR(Cleaned_Data[[#This Row],[Discount]]<0,Cleaned_Data[[#This Row],[Discount]]>1),"Check discount","OK") -> OK | U4: =IF(Cleaned_Data[[#This Row],[Current Price]]>Cleaned_Data[[#This Row],[Old Price]],"Check prices","OK") -> OK
A5: Weighing Scale Digital Bathroom Body Fat Scale USB-Black | B5: 1580 | C5: 2499 | D5: 0.37 | E5: 7 | F5: 4.7 | G5: =Cleaned_Data[[#This Row],[Old Price]]-Cleaned_Data[[#This Row],[Current Price]] -> 919 | H5: =IF(Cleaned_Data[[#This Row],[Rating]]="","Missing",IF(Cleaned_Data[[#This Row],[Rating]]<3,"Poor",IF(Cleaned_Data[[#This Row],[Rating]]<=4.5,"Average","Excellent"))) -> Excellent | I5: =IF( Cleaned_Data[[#This Row],[Discount]]="", "Missing", IF( Cleaned_Data[[#This Row],[Discount]]<20%, "Low Discount", IF( Cleaned_Data[[#This Row],[Discount]]<=40%, "Medium Discount", "High Discount" ) ) ) -> Medium Discount | J5: =IF( Cleaned_Data[[#This Row],[Current Price]]="", "Missing", IF( Cleaned_Data[[#This Row],[Current Price]]<=Analysis!$B$3, "Low Price", IF( Cleaned_Data[[#This Row],[Current Price]]<=Analysis!$B$4, "Medium Price", "High Price" ) ) ) -> Medium Price | K5: =IF(Cleaned_Data[[#This Row],[Review]]="","Missing",IF(Cleaned_Data[[#This Row],[Review]]>=Engagement_Threshold,"Strong Engagement","Weak Engagement")) -> Weak Engagement | L5: =IF(OR(Cleaned_Data[[#This Row],[Discount]]="",Cleaned_Data[[#This Row],[Rating]]=""),"Missing",IF(AND(Cleaned_Data[[#This Row],[Discount Category]]="High Discount",Cleaned_Data[[#This Row],[Rating Category]]="Poor"),"Flag","OK")) -> OK | M5: =IF(OR(Cleaned_Data[[#This Row],[Discount]]="",Cleaned_Data[[#This Row],[Review]]=""),"Missing",IF(AND(Cleaned_Data[[#This Row],[Discount Category]]="High Discount",Cleaned_Data[[#This Row],[Engagement]]="Weak Engagement"),"Flag","OK")) -> OK | N5: =IF(OR(Cleaned_Data[[#This Row],[Review]]="",Cleaned_Data[[#This Row],[Rating]]=""),"Missing",IF(AND(Cleaned_Data[[#This Row],[Engagement]]="Strong Engagement",Cleaned_Data[[#This Row],[Rating Category]]="Average"),"Flag","OK")) -> OK | O5: =IF(OR(Cleaned_Data[[#This Row],[Review]]="",Cleaned_Data[[#This Row],[Rating]]=""),"Missing",IF(AND(Cleaned_Data[[#This Row],[Engagement]]="Strong Engagement",Cleaned_Data[[#This Row],[Rating Category]]="Excellent"),"Flag","OK")) -> OK | P5: =IF(Cleaned_Data[[#This Row],[Rating]]="","Missing Rating","Has Rating") -> Has Rating | Q5: =IFERROR( (Cleaned_Data[[#This Row],[Old Price]]-Cleaned_Data[[#This Row],[Current Price]])/Cleaned_Data[[#This Row],[Old Price]], "" ) -> 0.3677471 | R5: =IF( Cleaned_Data[[#This Row],[Discount]] - Cleaned_Data[[#This Row],[Calculated Discount]]>2%, "Check", "OK" ) -> OK | S5: =IF(OR(Cleaned_Data[[#This Row],[Rating]]<0,Cleaned_Data[[#This Row],[Rating]]>5),"Check rating","OK") -> OK | T5: =IF(OR(Cleaned_Data[[#This Row],[Discount]]<0,Cleaned_Data[[#This Row],[Discount]]>1),"Check discount","OK") -> OK | U5: =IF(Cleaned_Data[[#This Row],[Current Price]]>Cleaned_Data[[#This Row],[Old Price]],"Check prices","OK") -> OK
A6: Portable Home Small Air Humidifier 3-Speed Fan - Green | B6: 1740 | C6: 2356 | D6: 0.26 | E6: 5 | F6: 4.8 | G6: =Cleaned_Data[[#This Row],[Old Price]]-Cleaned_Data[[#This Row],[Current Price]] -> 616 | H6: =IF(Cleaned_Data[[#This Row],[Rating]]="","Missing",IF(Cleaned_Data[[#This Row],[Rating]]<3,"Poor",IF(Cleaned_Data[[#This Row],[Rating]]<=4.5,"Average","Excellent"))) -> Excellent | I6: =IF( Cleaned_Data[[#This Row],[Discount]]="", "Missing", IF( Cleaned_Data[[#This Row],[Discount]]<20%, "Low Discount", IF( Cleaned_Data[[#This Row],[Discount]]<=40%, "Medium Discount", "High Discount" ) ) ) -> Medium Discount | J6: =IF( Cleaned_Data[[#This Row],[Current Price]]="", "Missing", IF( Cleaned_Data[[#This Row],[Current Price]]<=Analysis!$B$3, "Low Price", IF( Cleaned_Data[[#This Row],[Current Price]]<=Analysis!$B$4, "Medium Price", "High Price" ) ) ) -> High Price | K6: =IF(Cleaned_Data[[#This Row],[Review]]="","Missing",IF(Cleaned_Data[[#This Row],[Review]]>=Engagement_Threshold,"Strong Engagement","Weak Engagement")) -> Weak Engagement | L6: =IF(OR(Cleaned_Data[[#This Row],[Discount]]="",Cleaned_Data[[#This Row],[Rating]]=""),"Missing",IF(AND(Cleaned_Data[[#This Row],[Discount Category]]="High Discount",Cleaned_Data[[#This Row],[Rating Category]]="Poor"),"Flag","OK")) -> OK | M6: =IF(OR(Cleaned_Data[[#This Row],[Discount]]="",Cleaned_Data[[#This Row],[Review]]=""),"Missing",IF(AND(Cleaned_Data[[#This Row],[Discount Category]]="High Discount",Cleaned_Data[[#This Row],[Engagement]]="Weak Engagement"),"Flag","OK")) -> OK | N6: =IF(OR(Cleaned_Data[[#This Row],[Review]]="",Cleaned_Data[[#This Row],[Rating]]=""),"Missing",IF(AND(Cleaned_Data[[#This Row],[Engagement]]="Strong Engagement",Cleaned_Data[[#This Row],[Rating Category]]="Average"),"Flag","OK")) -> OK | O6: =IF(OR(Cleaned_Data[[#This Row],[Review]]="",Cleaned_Data[[#This Row],[Rating]]=""),"Missing",IF(AND(Cleaned_Data[[#This Row],[Engagement]]="Strong Engagement",Cleaned_Data[[#This Row],[Rating Category]]="Excellent"),"Flag","OK")) -> OK | P6: =IF(Cleaned_Data[[#This Row],[Rating]]="","Missing Rating","Has Rating") -> Has Rating | Q6: =IFERROR( (Cleaned_Data[[#This Row],[Old Price]]-Cleaned_Data[[#This Row],[Current Price]])/Cleaned_Data[[#This Row],[Old Price]], "" ) -> 0.2614601 | R6: =IF( Cleaned_Data[[#This Row],[Discount]] - Cleaned_Data[[#This Row],[Calculated Discount]]>2%, "Check", "OK" ) -> OK | S6: =IF(OR(Cleaned_Data[[#This Row],[Rating]]<0,Cleaned_Data[[#This Row],[Rating]]>5),"Check rating","OK") -> OK | T6: =IF(OR(Cleaned_Data[[#This Row],[Discount]]<0,Cleaned_Data[[#This Row],[Discount]]>1),"Check discount","OK") -> OK | U6: =IF(Cleaned_Data[[#This Row],[Current Price]]>Cleaned_Data[[#This Row],[Old Price]],"Check prices","OK") -> OK
A7: 220V 60W Electric Soldering Iron Kits With Tools, Tips, And Multimeter | B7: 2999 | C7: 3290 | D7: 0.09 | E7: 15 | F7: 4 | G7: =Cleaned_Data[[#This Row],[Old Price]]-Cleaned_Data[[#This Row],[Current Price]] -> 291 | H7: =IF(Cleaned_Data[[#This Row],[Rating]]="","Missing",IF(Cleaned_Data[[#This Row],[Rating]]<3,"Poor",IF(Cleaned_Data[[#This Row],[Rating]]<=4.5,"Average","Excellent"))) -> Average | I7: =IF( Cleaned_Data[[#This Row],[Discount]]="", "Missing", IF( Cleaned_Data[[#This Row],[Discount]]<20%, "Low Discount", IF( Cleaned_Data[[#This Row],[Discount]]<=40%, "Medium Discount", "High Discount" ) ) ) -> Low Discount | J7: =IF( Cleaned_Data[[#This Row],[Current Price]]="", "Missing", IF( Cleaned_Data[[#This Row],[Current Price]]<=Analysis!$B$3, "Low Price", IF( Cleaned_Data[[#This Row],[Current Price]]<=Analysis!$B$4, "Medium Price", "High Price" ) ) ) -> High Price | K7: =IF(Cleaned_Data[[#This Row],[Review]]="","Missing",IF(Cleaned_Data[[#This Row],[Review]]>=Engagement_Threshold,"Strong Engagement","Weak Engagement")) -> Strong Engagement | L7: =IF(OR(Cleaned_Data[[#This Row],[Discount]]="",Cleaned_Data[[#This Row],[Rating]]=""),"Missing",IF(AND(Cleaned_Data[[#This Row],[Discount Category]]="High Discount",Cleaned_Data[[#This Row],[Rating Category]]="Poor"),"Flag","OK")) -> OK | M7: =IF(OR(Cleaned_Data[[#This Row],[Discount]]="",Cleaned_Data[[#This Row],[Review]]=""),"Missing",IF(AND(Cleaned_Data[[#This Row],[Discount Category]]="High Discount",Cleaned_Data[[#This Row],[Engagement]]="Weak Engagement"),"Flag","OK")) -> OK | N7: =IF(OR(Cleaned_Data[[#This Row],[Review]]="",Cleaned_Data[[#This Row],[Rating]]=""),"Missing",IF(AND(Cleaned_Data[[#This Row],[Engagement]]="Strong Engagement",Cleaned_Data[[#This Row],[Rating Category]]="Average"),"Flag","OK")) -> Flag | O7: =IF(OR(Cleaned_Data[[#This Row],[Review]]="",Cleaned_Data[[#This Row],[Rating]]=""),"Missing",IF(AND(Cleaned_Data[[#This Row],[Engagement]]="Strong Engagement",Cleaned_Data[[#This Row],[Rating Category]]="Excellent"),"Flag","OK")) -> OK | P7: =IF(Cleaned_Data[[#This Row],[Rating]]="","Missing Rating","Has Rating") -> Has Rating | Q7: =IFERROR( (Cleaned_Data[[#This Row],[Old Price]]-Cleaned_Data[[#This Row],[Current Price]])/Cleaned_Data[[#This Row],[Old Price]], "" ) -> 0.088449848 | R7: =IF( Cleaned_Data[[#This Row],[Discount]] - Cleaned_Data[[#This Row],[Calculated Discount]]>2%, "Check", "OK" ) -> OK | S7: =IF(OR(Cleaned_Data[[#This Row],[Rating]]<0,Cleaned_Data[[#This Row],[Rating]]>5),"Check rating","OK") -> OK | T7: =IF(OR(Cleaned_Data[[#This Row],[Discount]]<0,Cleaned_Data[[#This Row],[Discount]]>1),"Check discount","OK") -> OK | U7: =IF(Cleaned_Data[[#This Row],[Current Price]]>Cleaned_Data[[#This Row],[Old Price]],"Check prices","OK") -> OK
A8: 137 Pieces Cake Decorating Tool Set Baking Supplies | B8: 2319 | C8: 3032 | D8: 0.24 | E8: 55 | F8: 4.6 | G8: =Cleaned_Data[[#This Row],[Old Price]]-Cleaned_Data[[#This Row],[Current Price]] -> 713 | H8: =IF(Cleaned_Data[[#This Row],[Rating]]="","Missing",IF(Cleaned_Data[[#This Row],[Rating]]<3,"Poor",IF(Cleaned_Data[[#This Row],[Rating]]<=4.5,"Average","Excellent"))) -> Excellent | I8: =IF( Cleaned_Data[[#This Row],[Discount]]="", "Missing", IF( Cleaned_Data[[#This Row],[Discount]]<20%, "Low Discount", IF( Cleaned_Data[[#This Row],[Discount]]<=40%, "Medium Discount", "High Discount" ) ) ) -> Medium Discount | J8: =IF( Cleaned_Data[[#This Row],[Current Price]]="", "Missing", IF( Cleaned_Data[[#This Row],[Current Price]]<=Analysis!$B$3, "Low Price", IF( Cleaned_Data[[#This Row],[Current Price]]<=Analysis!$B$4, "Medium Price", "High Price" ) ) ) -> High Price | K8: =IF(Cleaned_Data[[#This Row],[Review]]="","Missing",IF(Cleaned_Data[[#This Row],[Review]]>=Engagement_Threshold,"Strong Engagement","Weak Engagement")) -> Strong Engagement | L8: =IF(OR(Cleaned_Data[[#This Row],[Discount]]="",Cleaned_Data[[#This Row],[Rating]]=""),"Missing",IF(AND(Cleaned_Data[[#This Row],[Discount Category]]="High Discount",Cleaned_Data[[#This Row],[Rating Category]]="Poor"),"Flag","OK")) -> OK | M8: =IF(OR(Cleaned_Data[[#This Row],[Discount]]="",Cleaned_Data[[#This Row],[Review]]=""),"Missing",IF(AND(Cleaned_Data[[#This Row],[Discount Category]]="High Discount",Cleaned_Data[[#This Row],[Engagement]]="Weak Engagement"),"Flag","OK")) -> OK | N8: =IF(OR(Cleaned_Data[[#This Row],[Review]]="",Cleaned_Data[[#This Row],[Rating]]=""),"Missing",IF(AND(Cleaned_Data[[#This Row],[Engagement]]="Strong Engagement",Cleaned_Data[[#This Row],[Rating Category]]="Average"),"Flag","OK")) -> OK | O8: =IF(OR(Cleaned_Data[[#This Row],[Review]]="",Cleaned_Data[[#This Row],[Rating]]=""),"Missing",IF(AND(Cleaned_Data[[#This Row],[Engagement]]="Strong Engagement",Cleaned_Data[[#This Row],[Rating Category]]="Excellent"),"Flag","OK")) -> Flag | P8: =IF(Cleaned_Data[[#This Row],[Rating]]="","Missing Rating","Has Rating") -> Has Rating | Q8: =IFERROR( (Cleaned_Data[[#This Row],[Old Price]]-Cleaned_Data[[#This Row],[Current Price]])/Cleaned_Data[[#This Row],[Old Price]], "" ) -> 0.23515831 | R8: =IF( Cleaned_Data[[#This Row],[Discount]] - Cleaned_Data[[#This Row],[Calculated Discount]]>2%, "Check", "OK" ) -> OK | S8: =IF(OR(Cleaned_Data[[#This Row],[Rating]]<0,Cleaned_Data[[#This Row],[Rating]]>5),"Check rating","OK") -> OK | T8: =IF(OR(Cleaned_Data[[#This Row],[Discount]]<0,Cleaned_Data[[#This Row],[Discount]]>1),"Check discount","OK") -> OK | U8: =IF(Cleaned_Data[[#This Row],[Current Price]]>Cleaned_Data[[#This Row],[Old Price]],"Check prices","OK") -> OK
A9: Desk Foldable Fan Adjustable Fan Strong Wind 3 Gear Usb | B9: 988 | C9: 1580 | D9: 0.37 | E9: 2 | F9: 4 | G9: =Cleaned_Data[[#This Row],[Old Price]]-Cleaned_Data[[#This Row],[Current Price]] -> 592 | H9: =IF(Cleaned_Data[[#This Row],[Rating]]="","Missing",IF(Cleaned_Data[[#This Row],[Rating]]<3,"Poor",IF(Cleaned_Data[[#This Row],[Rating]]<=4.5,"Average","Excellent"))) -> Average | I9: =IF( Cleaned_Data[[#This Row],[Discount]]="", "Missing", IF( Cleaned_Data[[#This Row],[Discount]]<20%, "Low Discount", IF( Cleaned_Data[[#This Row],[Discount]]<=40%, "Medium Discount", "High Discount" ) ) ) -> Medium Discount | J9: =IF( Cleaned_Data[[#This Row],[Current Price]]="", "Missing", IF( Cleaned_Data[[#This Row],[Current Price]]<=Analysis!$B$3, "Low Price", IF( Cleaned_Data[[#This Row],[Current Price]]<=Analysis!$B$4, "Medium Price", "High Price" ) ) ) -> Medium Price | K9: =IF(Cleaned_Data[[#This Row],[Review]]="","Missing",IF(Cleaned_Data[[#This Row],[Review]]>=Engagement_Threshold,"Strong Engagement","Weak Engagement")) -> Weak Engagement | L9: =IF(OR(Cleaned_Data[[#This Row],[Discount]]="",Cleaned_Data[[#This Row],[Rating]]=""),"Missing",IF(AND(Cleaned_Data[[#This Row],[Discount Category]]="High Discount",Cleaned_Data[[#This Row],[Rating Category]]="Poor"),"Flag","OK")) -> OK | M9: =IF(OR(Cleaned_Data[[#This Row],[Discount]]="",Cleaned_Data[[#This Row],[Review]]=""),"Missing",IF(AND(Cleaned_Data[[#This Row],[Discount Category]]="High Discount",Cleaned_Data[[#This Row],[Engagement]]="Weak Engagement"),"Flag","OK")) -> OK | N9: =IF(OR(Cleaned_Data[[#This Row],[Review]]="",Cleaned_Data[[#This Row],[Rating]]=""),"Missing",IF(AND(Cleaned_Data[[#This Row],[Engagement]]="Strong Engagement",Cleaned_Data[[#This Row],[Rating Category]]="Average"),"Flag","OK")) -> OK | O9: =IF(OR(Cleaned_Data[[#This Row],[Review]]="",Cleaned_Data[[#This Row],[Rating]]=""),"Missing",IF(AND(Cleaned_Data[[#This Row],[Engagement]]="Strong Engagement",Cleaned_Data[[#This Row],[Rating Category]]="Excellent"),"Flag","OK")) -> OK | P9: =IF(Cleaned_Data[[#This Row],[Rating]]="","Missing Rating","Has Rating") -> Has Rating | Q9: =IFERROR( (Cleaned_Data[[#This Row],[Old Price]]-Cleaned_Data[[#This Row],[Current Price]])/Cleaned_Data[[#This Row],[Old Price]], "" ) -> 0.37468354 | R9: =IF( Cleaned_Data[[#This Row],[Discount]] - Cleaned_Data[[#This Row],[Calculated Discount]]>2%, "Check", "OK" ) -> OK | S9: =IF(OR(Cleaned_Data[[#This Row],[Rating]]<0,Cleaned_Data[[#This Row],[Rating]]>5),"Check rating","OK") -> OK | T9: =IF(OR(Cleaned_Data[[#This Row],[Discount]]<0,Cleaned_Data[[#This Row],[Discount]]>1),"Check discount","OK") -> OK | U9: =IF(Cleaned_Data[[#This Row],[Current Price]]>Cleaned_Data[[#This Row],[Old Price]],"Check prices","OK") -> OK
A10: LASA FOLDING TABLE SERVING STAND | B10: 1274 | C10: 2800 | D10: 0.55 | E10: 5 | F10: 4.8 | G10: =Cleaned_Data[[#This Row],[Old Price]]-Cleaned_Data[[#This Row],[Current Price]] -> 1526 | H10: =IF(Cleaned_Data[[#This Row],[Rating]]="","Missing",IF(Cleaned_Data[[#This Row],[Rating]]<3,"Poor",IF(Cleaned_Data[[#This Row],[Rating]]<=4.5,"Average","Excellent"))) -> Excellent | I10: =IF( Cleaned_Data[[#This Row],[Discount]]="", "Missing", IF( Cleaned_Data[[#This Row],[Discount]]<20%, "Low Discount", IF( Cleaned_Data[[#This Row],[Discount]]<=40%, "Medium Discount", "High Discount" ) ) ) -> High Discount | J10: =IF( Cleaned_Data[[#This Row],[Current Price]]="", "Missing", IF( Cleaned_Data[[#This Row],[Current Price]]<=Analysis!$B$3, "Low Price", IF( Cleaned_Data[[#This Row],[Current Price]]<=Analysis!$B$4, "Medium Price", "High Price" ) ) ) -> Medium Price | K10: =IF(Cleaned_Data[[#This Row],[Review]]="","Missing",IF(Cleaned_Data[[#This Row],[Review]]>=Engagement_Threshold,"Strong Engagement","Weak Engagement")) -> Weak Engagement | L10: =IF(OR(Cleaned_Data[[#This Row],[Discount]]="",Cleaned_Data[[#This Row],[Rating]]=""),"Missing",IF(AND(Cleaned_Data[[#This Row],[Discount Category]]="High Discount",Cleaned_Data[[#This Row],[Rating Category]]="Poor"),"Flag","OK")) -> OK | M10: =IF(OR(Cleaned_Data[[#This Row],[Discount]]="",Cleaned_Data[[#This Row],[Review]]=""),"Missing",IF(AND(Cleaned_Data[[#This Row],[Discount Category]]="High Discount",Cleaned_Data[[#This Row],[Engagement]]="Weak Engagement"),"Flag","OK")) -> Flag | N10: =IF(OR(Cleaned_Data[[#This Row],[Review]]="",Cleaned_Data[[#This Row],[Rating]]=""),"Missing",IF(AND(Cleaned_Data[[#This Row],[Engagement]]="Strong Engagement",Cleaned_Data[[#This Row],[Rating Category]]="Average"),"Flag","OK")) -> OK | O10: =IF(OR(Cleaned_Data[[#This Row],[Review]]="",Cleaned_Data[[#This Row],[Rating]]=""),"Missing",IF(AND(Cleaned_Data[[#This Row],[Engagement]]="Strong Engagement",Cleaned_Data[[#This Row],[Rating Category]]="Excellent"),"Flag","OK")) -> OK | P10: =IF(Cleaned_Data[[#This Row],[Rating]]="","Missing Rating","Has Rating") -> Has Rating | Q10: =IFERROR( (Cleaned_Data[[#This Row],[Old Price]]-Cleaned_Data[[#This Row],[Current Price]])/Cleaned_Data[[#This Row],[Old Price]], "" ) -> 0.545 | R10: =IF( Cleaned_Data[[#This Row],[Discount]] - Cleaned_Data[[#This Row],[Calculated Discount]]>2%, "Check", "OK" ) -> OK | S10: =IF(OR(Cleaned_Data[[#This Row],[Rating]]<0,Cleaned_Data[[#This Row],[Rating]]>5),"Check rating","OK") -> OK | T10: =IF(OR(Cleaned_Data[[#This Row],[Discount]]<0,Cleaned_Data[[#This Row],[Discount]]>1),"Check discount","OK") -> OK | U10: =IF(Cleaned_Data[[#This Row],[Current Price]]>Cleaned_Data[[#This Row],[Old Price]],"Check prices","OK") -> OK
A11: 13 In 1 Home Repair Tools Box Kit Set | B11: 1600 | C11: 2929 | D11: 0.45 | E11: 5 | F11: 3.8 | G11: =Cleaned_Data[[#This Row],[Old Price]]-Cleaned_Data[[#This Row],[Current Price]] -> 1329 | H11: =IF(Cleaned_Data[[#This Row],[Rating]]="","Missing",IF(Cleaned_Data[[#This Row],[Rating]]<3,"Poor",IF(Cleaned_Data[[#This Row],[Rating]]<=4.5,"Average","Excellent"))) -> Average | I11: =IF( Cleaned_Data[[#This Row],[Discount]]="", "Missing", IF( Cleaned_Data[[#This Row],[Discount]]<20%, "Low Discount", IF( Cleaned_Data[[#This Row],[Discount]]<=40%, "Medium Discount", "High Discount" ) ) ) -> High Discount | J11: =IF( Cleaned_Data[[#This Row],[Current Price]]="", "Missing", IF( Cleaned_Data[[#This Row],[Current Price]]<=Analysis!$B$3, "Low Price", IF( Cleaned_Data[[#This Row],[Current Price]]<=Analysis!$B$4, "Medium Price", "High Price" ) ) ) -> Medium Price | K11: =IF(Cleaned_Data[[#This Row],[Review]]="","Missing",IF(Cleaned_Data[[#This Row],[Review]]>=Engagement_Threshold,"Strong Engagement","Weak Engagement")) -> Weak Engagement | L11: =IF(OR(Cleaned_Data[[#This Row],[Discount]]="",Cleaned_Data[[#This Row],[Rating]]=""),"Missing",IF(AND(Cleaned_Data[[#This Row],[Discount Category]]="High Discount",Cleaned_Data[[#This Row],[Rating Category]]="Poor"),"Flag","OK")) -> OK | M11: =IF(OR(Cleaned_Data[[#This Row],[Discount]]="",Cleaned_Data[[#This Row],[Review]]=""),"Missing",IF(AND(Cleaned_Data[[#This Row],[Discount Category]]="High Discount",Cleaned_Data[[#This Row],[Engagement]]="Weak Engagement"),"Flag","OK")) -> Flag | N11: =IF(OR(Cleaned_Data[[#This Row],[Review]]="",Cleaned_Data[[#This Row],[Rating]]=""),"Missing",IF(AND(Cleaned_Data[[#This Row],[Engagement]]="Strong Engagement",Cleaned_Data[[#This Row],[Rating Category]]="Average"),"Flag","OK")) -> OK | O11: =IF(OR(Cleaned_Data[[#This Row],[Review]]="",Cleaned_Data[[#This Row],[Rating]]=""),"Missing",IF(AND(Cleaned_Data[[#This Row],[Engagement]]="Strong Engagement",Cleaned_Data[[#This Row],[Rating Category]]="Excellent"),"Flag","OK")) -> OK | P11: =IF(Cleaned_Data[[#This Row],[Rating]]="","Missing Rating","Has Rating") -> Has Rating | Q11: =IFERROR( (Cleaned_Data[[#This Row],[Old Price]]-Cleaned_Data[[#This Row],[Current Price]])/Cleaned_Data[[#This Row],[Old Price]], "" ) -> 0.45373848 | R11: =IF( Cleaned_Data[[#This Row],[Discount]] - Cleaned_Data[[#This Row],[Calculated Discount]]>2%, "Check", "OK" ) -> OK | S11: =IF(OR(Cleaned_Data[[#This Row],[Rating]]<0,Cleaned_Data[[#This Row],[Rating]]>5),"Check rating","OK") -> OK | T11: =IF(OR(Cleaned_Data[[#This Row],[Discount]]<0,Cleaned_Data[[#This Row],[Discount]]>1),"Check discount","OK") -> OK | U11: =IF(Cleaned_Data[[#This Row],[Current Price]]>Cleaned_Data[[#This Row],[Old Price]],"Check prices","OK") -> OK
A12: Genebre 115 In 1 Screwdriver Repairing Tool Set For IPhone Cellphone Hand Tool | B12: 799 | C12: 999 | D12: 0.2 | E12: 12 | F12: 4.1 | G12: =Cleaned_Data[[#This Row],[Old Price]]-Cleaned_Data[[#This Row],[Current Price]] -> 200 | H12: =IF(Cleaned_Data[[#This Row],[Rating]]="","Missing",IF(Cleaned_Data[[#This Row],[Rating]]<3,"Poor",IF(Cleaned_Data[[#This Row],[Rating]]<=4.5,"Average","Excellent"))) -> Average | I12: =IF( Cleaned_Data[[#This Row],[Discount]]="", "Missing", IF( Cleaned_Data[[#This Row],[Discount]]<20%, "Low Discount", IF( Cleaned_Data[[#This Row],[Discount]]<=40%, "Medium Discount", "High Discount" ) ) ) -> Medium Discount | J12: =IF( Cleaned_Data[[#This Row],[Current Price]]="", "Missing", IF( Cleaned_Data[[#This Row],[Current Price]]<=Analysis!$B$3, "Low Price", IF( Cleaned_Data[[#This Row],[Current Price]]<=Analysis!$B$4, "Medium Price", "High Price" ) ) ) -> Medium Price | K12: =IF(Cleaned_Data[[#This Row],[Review]]="","Missing",IF(Cleaned_Data[[#This Row],[Review]]>=Engagement_Threshold,"Strong Engagement","Weak Engagement")) -> Weak Engagement | L12: =IF(OR(Cleaned_Data[[#This Row],[Discount]]="",Cleaned_Data[[#This Row],[Rating]]=""),"Missing",IF(AND(Cleaned_Data[[#This Row],[Discount Category]]="High Discount",Cleaned_Data[[#This Row],[Rating Category]]="Poor"),"Flag","OK")) -> OK | M12: =IF(OR(Cleaned_Data[[#This Row],[Discount]]="",Cleaned_Data[[#This Row],[Review]]=""),"Missing",IF(AND(Cleaned_Data[[#This Row],[Discount Category]]="High Discount",Cleaned_Data[[#This Row],[Engagement]]="Weak Engagement"),"Flag","OK")) -> OK | N12: =IF(OR(Cleaned_Data[[#This Row],[Review]]="",Cleaned_Data[[#This Row],[Rating]]=""),"Missing",IF(AND(Cleaned_Data[[#This Row],[Engagement]]="Strong Engagement",Cleaned_Data[[#This Row],[Rating Category]]="Average"),"Flag","OK")) -> OK | O12: =IF(OR(Cleaned_Data[[#This Row],[Review]]="",Cleaned_Data[[#This Row],[Rating]]=""),"Missing",IF(AND(Cleaned_Data[[#This Row],[Engagement]]="Strong Engagement",Cleaned_Data[[#This Row],[Rating Category]]="Excellent"),"Flag","OK")) -> OK | P12: =IF(Cleaned_Data[[#This Row],[Rating]]="","Missing Rating","Has Rating") -> Has Rating | Q12: =IFERROR( (Cleaned_Data[[#This Row],[Old Price]]-Cleaned_Data[[#This Row],[Current Price]])/Cleaned_Data[[#This Row],[Old Price]], "" ) -> 0.2002002 | R12: =IF( Cleaned_Data[[#This Row],[Discount]] - Cleaned_Data[[#This Row],[Calculated Discount]]>2%, "Check", "OK" ) -> OK | S12: =IF(OR(Cleaned_Data[[#This Row],[Rating]]<0,Cleaned_Data[[#This Row],[Rating]]>5),"Check rating","OK") -> OK | T12: =IF(OR(Cleaned_Data[[#This Row],[Discount]]<0,Cleaned_Data[[#This Row],[Discount]]>1),"Check discount","OK") -> OK | U12: =IF(Cleaned_Data[[#This Row],[Current Price]]>Cleaned_Data[[#This Row],[Old Price]],"Check prices","OK") -> OK
A13: 100 Pcs Crochet Hook Tool Set Knitting Hook Set With Box | B13: 990 | C13: 1500 | D13: 0.34 | E13: 39 | F13: 4.7 | G13: =Cleaned_Data[[#This Row],[Old Price]]-Cleaned_Data[[#This Row],[Current Price]] -> 510 | H13: =IF(Cleaned_Data[[#This Row],[Rating]]="","Missing",IF(Cleaned_Data[[#This Row],[Rating]]<3,"Poor",IF(Cleaned_Data[[#This Row],[Rating]]<=4.5,"Average","Excellent"))) -> Excellent | I13: =IF( Cleaned_Data[[#This Row],[Discount]]="", "Missing", IF( Cleaned_Data[[#This Row],[Discount]]<20%, "Low Discount", IF( Cleaned_Data[[#This Row],[Discount]]<=40%, "Medium Discount", "High Discount" ) ) ) -> Medium Discount | J13: =IF( Cleaned_Data[[#This Row],[Current Price]]="", "Missing", IF( Cleaned_Data[[#This Row],[Current Price]]<=Analysis!$B$3, "Low Price", IF( Cleaned_Data[[#This Row],[Current Price]]<=Analysis!$B$4, "Medium Price", "High Price" ) ) ) -> Medium Price | K13: =IF(Cleaned_Data[[#This Row],[Review]]="","Missing",IF(Cleaned_Data[[#This Row],[Review]]>=Engagement_Threshold,"Strong Engagement","Weak Engagement")) -> Strong Engagement | L13: =IF(OR(Cleaned_Data[[#This Row],[Discount]]="",Cleaned_Data[[#This Row],[Rating]]=""),"Missing",IF(AND(Cleaned_Data[[#This Row],[Discount Category]]="High Discount",Cleaned_Data[[#This Row],[Rating Category]]="Poor"),"Flag","OK")) -> OK | M13: =IF(OR(Cleaned_Data[[#This Row],[Discount]]="",Cleaned_Data[[#This Row],[Review]]=""),"Missing",IF(AND(Cleaned_Data[[#This Row],[Discount Category]]="High Discount",Cleaned_Data[[#This Row],[Engagement]]="Weak Engagement"),"Flag","OK")) -> OK | N13: =IF(OR(Cleaned_Data[[#This Row],[Review]]="",Cleaned_Data[[#This Row],[Rating]]=""),"Missing",IF(AND(Cleaned_Data[[#This Row],[Engagement]]="Strong Engagement",Cleaned_Data[[#This Row],[Rating Category]]="Average"),"Flag","OK")) -> OK | O13: =IF(OR(Cleaned_Data[[#This Row],[Review]]="",Cleaned_Data[[#This Row],[Rating]]=""),"Missing",IF(AND(Cleaned_Data[[#This Row],[Engagement]]="Strong Engagement",Cleaned_Data[[#This Row],[Rating Category]]="Excellent"),"Flag","OK")) -> Flag | P13: =IF(Cleaned_Data[[#This Row],[Rating]]="","Missing Rating","Has Rating") -> Has Rating | Q13: =IFERROR( (Cleaned_Data[[#This Row],[Old Price]]-Cleaned_Data[[#This Row],[Current Price]])/Cleaned_Data[[#This Row],[Old Price]], "" ) -> 0.34 | R13: =IF( Cleaned_Data[[#This Row],[Discount]] - Cleaned_Data[[#This Row],[Calculated Discount]]>2%, "Check", "OK" ) -> OK | S13: =IF(OR(Cleaned_Data[[#This Row],[Rating]]<0,Cleaned_Data[[#This Row],[Rating]]>5),"Check rating","OK") -> OK | T13: =IF(OR(Cleaned_Data[[#This Row],[Discount]]<0,Cleaned_Data[[#This Row],[Discount]]>1),"Check discount","OK") -> OK | U13: =IF(Cleaned_Data[[#This Row],[Current Price]]>Cleaned_Data[[#This Row],[Old Price]],"Check prices","OK") -> OK
... A22: 3PCS Single Head Knitting Crochet Sweater Needle Set | B22: 38 | C22: 80 | D22: 0.53 | E22: 13 | F22: 3.3 | G22: =Cleaned_Data[[#This Row],[Old Price]]-Cleaned_Data[[#This Row],[Current Price]] -> 42 | H22: =IF(Cleaned_Data[[#This Row],[Rating]]="","Missing",IF(Cleaned_Data[[#This Row],[Rating]]<3,"Poor",IF(Cleaned_Data[[#This Row],[Rating]]<=4.5,"Average","Excellent"))) -> Average | I22: =IF( Cleaned_Data[[#This Row],[Discount]]="", "Missing", IF( Cleaned_Data[[#This Row],[Discount]]<20%, "Low Discount", IF( Cleaned_Data[[#This Row],[Discount]]<=40%, "Medium Discount", "High Discount" ) ) ) -> High Discount | J22: =IF( Cleaned_Data[[#This Row],[Current Price]]="", "Missing", IF( Cleaned_Data[[#This Row],[Current Price]]<=Analysis!$B$3, "Low Price", IF( Cleaned_Data[[#This Row],[Current Price]]<=Analysis!$B$4, "Medium Price", "High Price" ) ) ) -> Low Price | K22: =IF(Cleaned_Data[[#This Row],[Review]]="","Missing",IF(Cleaned_Data[[#This Row],[Review]]>=Engagement_Threshold,"Strong Engagement","Weak Engagement")) -> Weak Engagement | L22: =IF(OR(Cleaned_Data[[#This Row],[Discount]]="",Cleaned_Data[[#This Row],[Rating]]=""),"Missing",IF(AND(Cleaned_Data[[#This Row],[Discount Category]]="High Discount",Cleaned_Data[[#This Row],[Rating Category]]="Poor"),"Flag","OK")) -> OK | M22: =IF(OR(Cleaned_Data[[#This Row],[Discount]]="",Cleaned_Data[[#This Row],[Review]]=""),"Missing",IF(AND(Cleaned_Data[[#This Row],[Discount Category]]="High Discount",Cleaned_Data[[#This Row],[Engagement]]="Weak Engagement"),"Flag","OK")) -> Flag | N22: =IF(OR(Cleaned_Data[[#This Row],[Review]]="",Cleaned_Data[[#This Row],[Rating]]=""),"Missing",IF(AND(Cleaned_Data[[#This Row],[Engagement]]="Strong Engagement",Cleaned_Data[[#This Row],[Rating Category]]="Average"),"Flag","OK")) -> OK | O22: =IF(OR(Cleaned_Data[[#This Row],[Review]]="",Cleaned_Data[[#This Row],[Rating]]=""),"Missing",IF(AND(Cleaned_Data[[#This Row],[Engagement]]="Strong Engagement",Cleaned_Data[[#This Row],[Rating Category]]="Excellent"),"Flag","OK")) -> OK | P22: =IF(Cleaned_Data[[#This Row],[Rating]]="","Missing Rating","Has Rating") -> Has Rating | Q22: =IFERROR( (Cleaned_Data[[#This Row],[Old Price]]-Cleaned_Data[[#This Row],[Current Price]])/Cleaned_Data[[#This Row],[Old Price]], "" ) -> 0.525 | R22: =IF( Cleaned_Data[[#This Row],[Discount]] - Cleaned_Data[[#This Row],[Calculated Discount]]>2%, "Check", "OK" ) -> OK | S22: =IF(OR(Cleaned_Data[[#This Row],[Rating]]<0,Cleaned_Data[[#This Row],[Rating]]>5),"Check rating","OK") -> OK | T22: =IF(OR(Cleaned_Data[[#This Row],[Discount]]<0,Cleaned_Data[[#This Row],[Discount]]>1),"Check discount","OK") -> OK | U22: =IF(Cleaned_Data[[#This Row],[Current Price]]>Cleaned_Data[[#This Row],[Old Price]],"Check prices","OK") -> OK
A23: 4pcs Bathroom/Kitchen Towel Rack,Roll Paper Holder,Towel Bars,Hook | B23: 1860 | C23: 3220 | D23: 0.42 | G23: =Cleaned_Data[[#This Row],[Old Price]]-Cleaned_Data[[#This Row],[Current Price]] -> 1360 | H23: =IF(Cleaned_Data[[#This Row],[Rating]]="","Missing",IF(Cleaned_Data[[#This Row],[Rating]]<3,"Poor",IF(Cleaned_Data[[#This Row],[Rating]]<=4.5,"Average","Excellent"))) -> Missing | I23: =IF( Cleaned_Data[[#This Row],[Discount]]="", "Missing", IF( Cleaned_Data[[#This Row],[Discount]]<20%, "Low Discount", IF( Cleaned_Data[[#This Row],[Discount]]<=40%, "Medium Discount", "High Discount" ) ) ) -> High Discount | J23: =IF( Cleaned_Data[[#This Row],[Current Price]]="", "Missing", IF( Cleaned_Data[[#This Row],[Current Price]]<=Analysis!$B$3, "Low Price", IF( Cleaned_Data[[#This Row],[Current Price]]<=Analysis!$B$4, "Medium Price", "High Price" ) ) ) -> High Price | K23: =IF(Cleaned_Data[[#This Row],[Review]]="","Missing",IF(Cleaned_Data[[#This Row],[Review]]>=Engagement_Threshold,"Strong Engagement","Weak Engagement")) -> Missing | L23: =IF(OR(Cleaned_Data[[#This Row],[Discount]]="",Cleaned_Data[[#This Row],[Rating]]=""),"Missing",IF(AND(Cleaned_Data[[#This Row],[Discount Category]]="High Discount",Cleaned_Data[[#This Row],[Rating Category]]="Poor"),"Flag","OK")) -> Missing | M23: =IF(OR(Cleaned_Data[[#This Row],[Discount]]="",Cleaned_Data[[#This Row],[Review]]=""),"Missing",IF(AND(Cleaned_Data[[#This Row],[Discount Category]]="High Discount",Cleaned_Data[[#This Row],[Engagement]]="Weak Engagement"),"Flag","OK")) -> Missing | N23: =IF(OR(Cleaned_Data[[#This Row],[Review]]="",Cleaned_Data[[#This Row],[Rating]]=""),"Missing",IF(AND(Cleaned_Data[[#This Row],[Engagement]]="Strong Engagement",Cleaned_Data[[#This Row],[Rating Category]]="Average"),"Flag","OK")) -> Missing | O23: =IF(OR(Cleaned_Data[[#This Row],[Review]]="",Cleaned_Data[[#This Row],[Rating]]=""),"Missing",IF(AND(Cleaned_Data[[#This Row],[Engagement]]="Strong Engagement",Cleaned_Data[[#This Row],[Rating Category]]="Excellent"),"Flag","OK")) -> Missing | P23: =IF(Cleaned_Data[[#This Row],[Rating]]="","Missing Rating","Has Rating") -> Missing Rating | Q23: =IFERROR( (Cleaned_Data[[#This Row],[Old Price]]-Cleaned_Data[[#This Row],[Current Price]])/Cleaned_Data[[#This Row],[Old Price]], "" ) -> 0.42236025 | R23: =IF( Cleaned_Data[[#This Row],[Discount]] - Cleaned_Data[[#This Row],[Calculated Discount]]>2%, "Check", "OK" ) -> OK | S23: =IF(OR(Cleaned_Data[[#This Row],[Rating]]<0,Cleaned_Data[[#This Row],[Rating]]>5),"Check rating","OK") -> OK | T23: =IF(OR(Cleaned_Data[[#This Row],[Discount]]<0,Cleaned_Data[[#This Row],[Discount]]>1),"Check discount","OK") -> OK | U23: =IF(Cleaned_Data[[#This Row],[Current Price]]>Cleaned_Data[[#This Row],[Old Price]],"Check prices","OK") -> OK
A24: LED Romantic Spaceship Starry Sky Projector,Children's Bedroom Night Light-Blue | B24: 880 | C24: 1350 | D24: 0.35 | E24: 6 | F24: 4 | G24: =Cleaned_Data[[#This Row],[Old Price]]-Cleaned_Data[[#This Row],[Current Price]] -> 470 | H24: =IF(Cleaned_Data[[#This Row],[Rating]]="","Missing",IF(Cleaned_Data[[#This Row],[Rating]]<3,"Poor",IF(Cleaned_Data[[#This Row],[Rating]]<=4.5,"Average","Excellent"))) -> Average | I24: =IF( Cleaned_Data[[#This Row],[Discount]]="", "Missing", IF( Cleaned_Data[[#This Row],[Discount]]<20%, "Low Discount", IF( Cleaned_Data[[#This Row],[Discount]]<=40%, "Medium Discount", "High Discount" ) ) ) -> Medium Discount | J24: =IF( Cleaned_Data[[#This Row],[Current Price]]="", "Missing", IF( Cleaned_Data[[#This Row],[Current Price]]<=Analysis!$B$3, "Low Price", IF( Cleaned_Data[[#This Row],[Current Price]]<=Analysis!$B$4, "Medium Price", "High Price" ) ) ) -> Medium Price | K24: =IF(Cleaned_Data[[#This Row],[Review]]="","Missing",IF(Cleaned_Data[[#This Row],[Review]]>=Engagement_Threshold,"Strong Engagement","Weak Engagement")) -> Weak Engagement | L24: =IF(OR(Cleaned_Data[[#This Row],[Discount]]="",Cleaned_Data[[#This Row],[Rating]]=""),"Missing",IF(AND(Cleaned_Data[[#This Row],[Discount Category]]="High Discount",Cleaned_Data[[#This Row],[Rating Category]]="Poor"),"Flag","OK")) -> OK | M24: =IF(OR(Cleaned_Data[[#This Row],[Discount]]="",Cleaned_Data[[#This Row],[Review]]=""),"Missing",IF(AND(Cleaned_Data[[#This Row],[Discount Category]]="High Discount",Cleaned_Data[[#This Row],[Engagement]]="Weak Engagement"),"Flag","OK")) -> OK | N24: =IF(OR(Cleaned_Data[[#This Row],[Review]]="",Cleaned_Data[[#This Row],[Rating]]=""),"Missing",IF(AND(Cleaned_Data[[#This Row],[Engagement]]="Strong Engagement",Cleaned_Data[[#This Row],[Rating Category]]="Average"),"Flag","OK")) -> OK | O24: =IF(OR(Cleaned_Data[[#This Row],[Review]]="",Cleaned_Data[[#This Row],[Rating]]=""),"Missing",IF(AND(Cleaned_Data[[#This Row],[Engagement]]="Strong Engagement",Cleaned_Data[[#This Row],[Rating Category]]="Excellent"),"Flag","OK")) -> OK | P24: =IF(Cleaned_Data[[#This Row],[Rating]]="","Missing Rating","Has Rating") -> Has Rating | Q24: =IFERROR( (Cleaned_Data[[#This Row],[Old Price]]-Cleaned_Data[[#This Row],[Current Price]])/Cleaned_Data[[#This Row],[Old Price]], "" ) -> 0.34814815 | R24: =IF( Cleaned_Data[[#This Row],[Discount]] - Cleaned_Data[[#This Row],[Calculated Discount]]>2%, "Check", "OK" ) -> OK | S24: =IF(OR(Cleaned_Data[[#This Row],[Rating]]<0,Cleaned_Data[[#This Row],[Rating]]>5),"Check rating","OK") -> OK | T24: =IF(OR(Cleaned_Data[[#This Row],[Discount]]<0,Cleaned_Data[[#This Row],[Discount]]>1),"Check discount","OK") -> OK | U24: =IF(Cleaned_Data[[#This Row],[Current Price]]>Cleaned_Data[[#This Row],[Old Price]],"Check prices","OK") -> OK
A25: Foldable Overbed Table/Desk | B25: 1650 | C25: 2150 | D25: 0.23 | E25: 14 | F25: 4.4 | G25: =Cleaned_Data[[#This Row],[Old Price]]-Cleaned_Data[[#This Row],[Current Price]] -> 500 | H25: =IF(Cleaned_Data[[#This Row],[Rating]]="","Missing",IF(Cleaned_Data[[#This Row],[Rating]]<3,"Poor",IF(Cleaned_Data[[#This Row],[Rating]]<=4.5,"Average","Excellent"))) -> Average | I25: =IF( Cleaned_Data[[#This Row],[Discount]]="", "Missing", IF( Cleaned_Data[[#This Row],[Discount]]<20%, "Low Discount", IF( Cleaned_Data[[#This Row],[Discount]]<=40%, "Medium Discount", "High Discount" ) ) ) -> Medium Discount | J25: =IF( Cleaned_Data[[#This Row],[Current Price]]="", "Missing", IF( Cleaned_Data[[#This Row],[Current Price]]<=Analysis!$B$3, "Low Price", IF( Cleaned_Data[[#This Row],[Current Price]]<=Analysis!$B$4, "Medium Price", "High Price" ) ) ) -> Medium Price | K25: =IF(Cleaned_Data[[#This Row],[Review]]="","Missing",IF(Cleaned_Data[[#This Row],[Review]]>=Engagement_Threshold,"Strong Engagement","Weak Engagement")) -> Strong Engagement | L25: =IF(OR(Cleaned_Data[[#This Row],[Discount]]="",Cleaned_Data[[#This Row],[Rating]]=""),"Missing",IF(AND(Cleaned_Data[[#This Row],[Discount Category]]="High Discount",Cleaned_Data[[#This Row],[Rating Category]]="Poor"),"Flag","OK")) -> OK | M25: =IF(OR(Cleaned_Data[[#This Row],[Discount]]="",Cleaned_Data[[#This Row],[Review]]=""),"Missing",IF(AND(Cleaned_Data[[#This Row],[Discount Category]]="High Discount",Cleaned_Data[[#This Row],[Engagement]]="Weak Engagement"),"Flag","OK")) -> OK | N25: =IF(OR(Cleaned_Data[[#This Row],[Review]]="",Cleaned_Data[[#This Row],[Rating]]=""),"Missing",IF(AND(Cleaned_Data[[#This Row],[Engagement]]="Strong Engagement",Cleaned_Data[[#This Row],[Rating Category]]="Average"),"Flag","OK")) -> Flag | O25: =IF(OR(Cleaned_Data[[#This Row],[Review]]="",Cleaned_Data[[#This Row],[Rating]]=""),"Missing",IF(AND(Cleaned_Data[[#This Row],[Engagement]]="Strong Engagement",Cleaned_Data[[#This Row],[Rating Category]]="Excellent"),"Flag","OK")) -> OK | P25: =IF(Cleaned_Data[[#This Row],[Rating]]="","Missing Rating","Has Rating") -> Has Rating | Q25: =IFERROR( (Cleaned_Data[[#This Row],[Old Price]]-Cleaned_Data[[#This Row],[Current Price]])/Cleaned_Data[[#This Row],[Old Price]], "" ) -> 0.23255814 | R25: =IF( Cleaned_Data[[#This Row],[Discount]] - Cleaned_Data[[#This Row],[Calculated Discount]]>2%, "Check", "OK" ) -> OK | S25: =IF(OR(Cleaned_Data[[#This Row],[Rating]]<0,Cleaned_Data[[#This Row],[Rating]]>5),"Check rating","OK") -> OK | T25: =IF(OR(Cleaned_Data[[#This Row],[Discount]]<0,Cleaned_Data[[#This Row],[Discount]]>1),"Check discount","OK") -> OK | U25: =IF(Cleaned_Data[[#This Row],[Current Price]]>Cleaned_Data[[#This Row],[Old Price]],"Check prices","OK") -> OK
A26: LASA 3 Tier Bamboo Shoe Bench Storage Shelf | B26: 2048 | C26: 4500 | D26: 0.54 | E26: 7 | F26: 4.3 | G26: =Cleaned_Data[[#This Row],[Old Price]]-Cleaned_Data[[#This Row],[Current Price]] -> 2452 | H26: =IF(Cleaned_Data[[#This Row],[Rating]]="","Missing",IF(Cleaned_Data[[#This Row],[Rating]]<3,"Poor",IF(Cleaned_Data[[#This Row],[Rating]]<=4.5,"Average","Excellent"))) -> Average | I26: =IF( Cleaned_Data[[#This Row],[Discount]]="", "Missing", IF( Cleaned_Data[[#This Row],[Discount]]<20%, "Low Discount", IF( Cleaned_Data[[#This Row],[Discount]]<=40%, "Medium Discount", "High Discount" ) ) ) -> High Discount | J26: =IF( Cleaned_Data[[#This Row],[Current Price]]="", "Missing", IF( Cleaned_Data[[#This Row],[Current Price]]<=Analysis!$B$3, "Low Price", IF( Cleaned_Data[[#This Row],[Current Price]]<=Analysis!$B$4, "Medium Price", "High Price" ) ) ) -> High Price | K26: =IF(Cleaned_Data[[#This Row],[Review]]="","Missing",IF(Cleaned_Data[[#This Row],[Review]]>=Engagement_Threshold,"Strong Engagement","Weak Engagement")) -> Weak Engagement | L26: =IF(OR(Cleaned_Data[[#This Row],[Discount]]="",Cleaned_Data[[#This Row],[Rating]]=""),"Missing",IF(AND(Cleaned_Data[[#This Row],[Discount Category]]="High Discount",Cleaned_Data[[#This Row],[Rating Category]]="Poor"),"Flag","OK")) -> OK | M26: =IF(OR(Cleaned_Data[[#This Row],[Discount]]="",Cleaned_Data[[#This Row],[Review]]=""),"Missing",IF(AND(Cleaned_Data[[#This Row],[Discount Category]]="High Discount",Cleaned_Data[[#This Row],[Engagement]]="Weak Engagement"),"Flag","OK")) -> Flag | N26: =IF(OR(Cleaned_Data[[#This Row],[Review]]="",Cleaned_Data[[#This Row],[Rating]]=""),"Missing",IF(AND(Cleaned_Data[[#This Row],[Engagement]]="Strong Engagement",Cleaned_Data[[#This Row],[Rating Category]]="Average"),"Flag","OK")) -> OK | O26: =IF(OR(Cleaned_Data[[#This Row],[Review]]="",Cleaned_Data[[#This Row],[Rating]]=""),"Missing",IF(AND(Cleaned_Data[[#This Row],[Engagement]]="Strong Engagement",Cleaned_Data[[#This Row],[Rating Category]]="Excellent"),"Flag","OK")) -> OK | P26: =IF(Cleaned_Data[[#This Row],[Rating]]="","Missing Rating","Has Rating") -> Has Rating | Q26: =IFERROR( (Cleaned_Data[[#This Row],[Old Price]]-Cleaned_Data[[#This Row],[Current Price]])/Cleaned_Data[[#This Row],[Old Price]], "" ) -> 0.54488889 | R26: =IF( Cleaned_Data[[#This Row],[Discount]] - Cleaned_Data[[#This Row],[Calculated Discount]]>2%, "Check", "OK" ) -> OK | S26: =IF(OR(Cleaned_Data[[#This Row],[Rating]]<0,Cleaned_Data[[#This Row],[Rating]]>5),"Check rating","OK") -> OK | T26: =IF(OR(Cleaned_Data[[#This Row],[Discount]]<0,Cleaned_Data[[#This Row],[Discount]]>1),"Check discount","OK") -> OK | U26: =IF(Cleaned_Data[[#This Row],[Current Price]]>Cleaned_Data[[#This Row],[Old Price]],"Check prices","OK") -> OK
A27: Electronic Digital Display Vernier Caliper | B27: 420 | C27: 647 | D27: 0.35 | E27: 49 | F27: 4.6 | G27: =Cleaned_Data[[#This Row],[Old Price]]-Cleaned_Data[[#This Row],[Current Price]] -> 227 | H27: =IF(Cleaned_Data[[#This Row],[Rating]]="","Missing",IF(Cleaned_Data[[#This Row],[Rating]]<3,"Poor",IF(Cleaned_Data[[#This Row],[Rating]]<=4.5,"Average","Excellent"))) -> Excellent | I27: =IF( Cleaned_Data[[#This Row],[Discount]]="", "Missing", IF( Cleaned_Data[[#This Row],[Discount]]<20%, "Low Discount", IF( Cleaned_Data[[#This Row],[Discount]]<=40%, "Medium Discount", "High Discount" ) ) ) -> Medium Discount | J27: =IF( Cleaned_Data[[#This Row],[Current Price]]="", "Missing", IF( Cleaned_Data[[#This Row],[Current Price]]<=Analysis!$B$3, "Low Price", IF( Cleaned_Data[[#This Row],[Current Price]]<=Analysis!$B$4, "Medium Price", "High Price" ) ) ) -> Low Price | K27: =IF(Cleaned_Data[[#This Row],[Review]]="","Missing",IF(Cleaned_Data[[#This Row],[Review]]>=Engagement_Threshold,"Strong Engagement","Weak Engagement")) -> Strong Engagement | L27: =IF(OR(Cleaned_Data[[#This Row],[Discount]]="",Cleaned_Data[[#This Row],[Rating]]=""),"Missing",IF(AND(Cleaned_Data[[#This Row],[Discount Category]]="High Discount",Cleaned_Data[[#This Row],[Rating Category]]="Poor"),"Flag","OK")) -> OK | M27: =IF(OR(Cleaned_Data[[#This Row],[Discount]]="",Cleaned_Data[[#This Row],[Review]]=""),"Missing",IF(AND(Cleaned_Data[[#This Row],[Discount Category]]="High Discount",Cleaned_Data[[#This Row],[Engagement]]="Weak Engagement"),"Flag","OK")) -> OK | N27: =IF(OR(Cleaned_Data[[#This Row],[Review]]="",Cleaned_Data[[#This Row],[Rating]]=""),"Missing",IF(AND(Cleaned_Data[[#This Row],[Engagement]]="Strong Engagement",Cleaned_Data[[#This Row],[Rating Category]]="Average"),"Flag","OK")) -> OK | O27: =IF(OR(Cleaned_Data[[#This Row],[Review]]="",Cleaned_Data[[#This Row],[Rating]]=""),"Missing",IF(AND(Cleaned_Data[[#This Row],[Engagement]]="Strong Engagement",Cleaned_Data[[#This Row],[Rating Category]]="Excellent"),"Flag","OK")) -> Flag | P27: =IF(Cleaned_Data[[#This Row],[Rating]]="","Missing Rating","Has Rating") -> Has Rating | Q27: =IFERROR( (Cleaned_Data[[#This Row],[Old Price]]-Cleaned_Data[[#This Row],[Current Price]])/Cleaned_Data[[#This Row],[Old Price]], "" ) -> 0.35085008 | R27: =IF( Cleaned_Data[[#This Row],[Discount]] - Cleaned_Data[[#This Row],[Calculated Discount]]>2%, "Check", "OK" ) -> OK | S27: =IF(OR(Cleaned_Data[[#This Row],[Rating]]<0,Cleaned_Data[[#This Row],[Rating]]>5),"Check rating","OK") -> OK | T27: =IF(OR(Cleaned_Data[[#This Row],[Discount]]<0,Cleaned_Data[[#This Row],[Discount]]>1),"Check discount","OK") -> OK | U27: =IF(Cleaned_Data[[#This Row],[Current Price]]>Cleaned_Data[[#This Row],[Old Price]],"Check prices","OK") -> OK
A28: Portable Wardrobe Nonwoven With 3 Hanging Rods And 6 Storage Shelves | B28: 2880 | C28: 3520 | D28: 0.18 | E28: 12 | F28: 3.8 | G28: =Cleaned_Data[[#This Row],[Old Price]]-Cleaned_Data[[#This Row],[Current Price]] -> 640 | H28: =IF(Cleaned_Data[[#This Row],[Rating]]="","Missing",IF(Cleaned_Data[[#This Row],[Rating]]<3,"Poor",IF(Cleaned_Data[[#This Row],[Rating]]<=4.5,"Average","Excellent"))) -> Average | I28: =IF( Cleaned_Data[[#This Row],[Discount]]="", "Missing", IF( Cleaned_Data[[#This Row],[Discount]]<20%, "Low Discount", IF( Cleaned_Data[[#This Row],[Discount]]<=40%, "Medium Discount", "High Discount" ) ) ) -> Low Discount | J28: =IF( Cleaned_Data[[#This Row],[Current Price]]="", "Missing", IF( Cleaned_Data[[#This Row],[Current Price]]<=Analysis!$B$3, "Low Price", IF( Cleaned_Data[[#This Row],[Current Price]]<=Analysis!$B$4, "Medium Price", "High Price" ) ) ) -> High Price | K28: =IF(Cleaned_Data[[#This Row],[Review]]="","Missing",IF(Cleaned_Data[[#This Row],[Review]]>=Engagement_Threshold,"Strong Engagement","Weak Engagement")) -> Weak Engagement | L28: =IF(OR(Cleaned_Data[[#This Row],[Discount]]="",Cleaned_Data[[#This Row],[Rating]]=""),"Missing",IF(AND(Cleaned_Data[[#This Row],[Discount Category]]="High Discount",Cleaned_Data[[#This Row],[Rating Category]]="Poor"),"Flag","OK")) -> OK | M28: =IF(OR(Cleaned_Data[[#This Row],[Discount]]="",Cleaned_Data[[#This Row],[Review]]=""),"Missing",IF(AND(Cleaned_Data[[#This Row],[Discount Category]]="High Discount",Cleaned_Data[[#This Row],[Engagement]]="Weak Engagement"),"Flag","OK")) -> OK | N28: =IF(OR(Cleaned_Data[[#This Row],[Review]]="",Cleaned_Data[[#This Row],[Rating]]=""),"Missing",IF(AND(Cleaned_Data[[#This Row],[Engagement]]="Strong Engagement",Cleaned_Data[[#This Row],[Rating Category]]="Average"),"Flag","OK")) -> OK | O28: =IF(OR(Cleaned_Data[[#This Row],[Review]]="",Cleaned_Data[[#This Row],[Rating]]=""),"Missing",IF(AND(Cleaned_Data[[#This Row],[Engagement]]="Strong Engagement",Cleaned_Data[[#This Row],[Rating Category]]="Excellent"),"Flag","OK")) -> OK | P28: =IF(Cleaned_Data[[#This Row],[Rating]]="","Missing Rating","Has Rating") -> Has Rating | Q28: =IFERROR( (Cleaned_Data[[#This Row],[Old Price]]-Cleaned_Data[[#This Row],[Current Price]])/Cleaned_Data[[#This Row],[Old Price]], "" ) -> 0.18181818 | R28: =IF( Cleaned_Data[[#This Row],[Discount]] - Cleaned_Data[[#This Row],[Calculated Discount]]>2%, "Check", "OK" ) -> OK | S28: =IF(OR(Cleaned_Data[[#This Row],[Rating]]<0,Cleaned_Data[[#This Row],[Rating]]>5),"Check rating","OK") -> OK | T28: =IF(OR(Cleaned_Data[[#This Row],[Discount]]<0,Cleaned_Data[[#This Row],[Discount]]>1),"Check discount","OK") -> OK | U28: =IF(Cleaned_Data[[#This Row],[Current Price]]>Cleaned_Data[[#This Row],[Old Price]],"Check prices","OK") -> OK
